Failure # 1 (occurred at 2023-01-02_17-41-21)
Traceback (most recent call last):
  File "/home/davidman/.local/lib/python3.10/site-packages/ray/tune/execution/ray_trial_executor.py", line 1070, in get_next_executor_event
    future_result = ray.get(ready_future)
  File "/home/davidman/.local/lib/python3.10/site-packages/ray/_private/client_mode_hook.py", line 105, in wrapper
    return func(*args, **kwargs)
  File "/home/davidman/.local/lib/python3.10/site-packages/ray/_private/worker.py", line 2311, in get
    raise value
ray.exceptions.RayActorError: The actor died because of an error raised in its creation task, [36mray::PPO.__init__()[39m (pid=52404, ip=10.0.0.21, repr=PPO)
  File "/home/davidman/.local/lib/python3.10/site-packages/ray/rllib/algorithms/algorithm.py", line 374, in __init__
    self._env_id, self.env_creator = self._get_env_id_and_creator(
  File "/home/davidman/.local/lib/python3.10/site-packages/ray/rllib/algorithms/algorithm.py", line 2130, in _get_env_id_and_creator
    return env_specifier, _global_registry.get(ENV_CREATOR, env_specifier)
  File "/home/davidman/.local/lib/python3.10/site-packages/ray/tune/registry.py", line 205, in get
    return pickle.loads(value)
AttributeError: Can't get attribute 'Powerplayer.observation_space' on <module '__main__' from '/home/davidman/.local/lib/python3.10/site-packages/ray/_private/workers/default_worker.py'>

