Failure # 1 (occurred at 2023-01-02_20-54-28)
Traceback (most recent call last):
  File "/home/davidman/.local/lib/python3.10/site-packages/ray/tune/execution/ray_trial_executor.py", line 1070, in get_next_executor_event
    future_result = ray.get(ready_future)
  File "/home/davidman/.local/lib/python3.10/site-packages/ray/_private/client_mode_hook.py", line 105, in wrapper
    return func(*args, **kwargs)
  File "/home/davidman/.local/lib/python3.10/site-packages/ray/_private/worker.py", line 2311, in get
    raise value
ray.exceptions.RayActorError: The actor died because of an error raised in its creation task, [36mray::PPO.__init__()[39m (pid=64012, ip=10.0.0.21, repr=PPO)
  File "/home/davidman/.local/lib/python3.10/site-packages/ray/rllib/evaluation/worker_set.py", line 239, in _setup
    self.add_workers(
  File "/home/davidman/.local/lib/python3.10/site-packages/ray/rllib/evaluation/worker_set.py", line 612, in add_workers
    raise result.get()
  File "/home/davidman/.local/lib/python3.10/site-packages/ray/rllib/utils/actor_manager.py", line 473, in __fetch_result
    result = ray.get(r)
ray.exceptions.RayActorError: The actor died because of an error raised in its creation task, [36mray::RolloutWorker.__init__()[39m (pid=64089, ip=10.0.0.21, repr=<ray.rllib.evaluation.rollout_worker.RolloutWorker object at 0x7f6aebf27100>)
  File "/home/davidman/.local/lib/python3.10/site-packages/ray/rllib/evaluation/rollout_worker.py", line 585, in __init__
    self.env = env_creator(copy.deepcopy(self.env_context))
  File "/home/davidman/Desktop/rl_dir/powerplayer-main/powerplayer/powerplayPZ.py", line 845, in <lambda>
    register_env(env_name, lambda config_: ParallelPettingZooEnv(env_creator(config_)))
  File "/home/davidman/.local/lib/python3.10/site-packages/ray/rllib/env/wrappers/pettingzoo_env.py", line 157, in __init__
    self.observation_space = self.par_env.observation_space(self.par_env.agents[0])
TypeError: 'dict' object is not callable

During handling of the above exception, another exception occurred:

[36mray::PPO.__init__()[39m (pid=64012, ip=10.0.0.21, repr=PPO)
  File "/home/davidman/.local/lib/python3.10/site-packages/ray/rllib/algorithms/algorithm.py", line 441, in __init__
    super().__init__(
  File "/home/davidman/.local/lib/python3.10/site-packages/ray/tune/trainable/trainable.py", line 169, in __init__
    self.setup(copy.deepcopy(self.config))
  File "/home/davidman/.local/lib/python3.10/site-packages/ray/rllib/algorithms/algorithm.py", line 566, in setup
    self.workers = WorkerSet(
  File "/home/davidman/.local/lib/python3.10/site-packages/ray/rllib/evaluation/worker_set.py", line 191, in __init__
    raise e.args[0].args[2]
TypeError: 'dict' object is not callable

